Workbook

Sheet Seasonal Electricity Trade
A1: WACC | B1: Scenario | C1: Model | D1: season | E1: Electricity Imports (TWh) | F1: Electricity Exports (TWh)
A2: 5 | B2: abroad-resnuc-low | C2: STEM | D2: summer | E2: ='[1]stem-seasonal-trade'!C3 -> 0.00029050976 | F2: ='[1]stem-seasonal-trade'!E3 -> 3.2846716
A3: 5 | B3: abroad-resnuc-medium | C3: STEM | D3: summer | E3: ='[1]stem-seasonal-trade'!C4 -> 0.0003357395 | F3: ='[1]stem-seasonal-trade'!E4 -> 1.9127066
A4: 5 | B4: abroad-resnuc-high | C4: STEM | D4: summer | E4: ='[1]stem-seasonal-trade'!C5 -> 0.57246808 | F4: ='[1]stem-seasonal-trade'!E5 -> 1.7713808
A5: 5 | B5: abroad-resnuc-phaseout | C5: STEM | D5: summer | E5: ='[1]stem-seasonal-trade'!C6 -> 1.538289 | F5: ='[1]stem-seasonal-trade'!E6 -> 1.3308959
A6: 5 | B6: abroad-res-low | C6: STEM | D6: summer | E6: ='[1]stem-seasonal-trade'!C7 -> 0.025316774 | F6: ='[1]stem-seasonal-trade'!E7 -> 1.899853
A7: 5 | B7: abroad-res-medium | C7: STEM | D7: summer | E7: ='[1]stem-seasonal-trade'!C8 -> 0.47208235 | F7: ='[1]stem-seasonal-trade'!E8 -> 1.7728259
A8: 5 | B8: abroad-res-high | C8: STEM | D8: summer | E8: ='[1]stem-seasonal-trade'!C9 -> 1.5077675 | F8: ='[1]stem-seasonal-trade'!E9 -> 1.3181046
A9: 5 | B9: abroad-res-phaseout | C9: STEM | D9: summer | E9: ='[1]stem-seasonal-trade'!C10 -> 1.5077675 | F9: ='[1]stem-seasonal-trade'!E10 -> 1.3181046
A10: 5 | B10: abroad-nores-low | C10: STEM | D10: summer | E10: ='[1]stem-seasonal-trade'!C11 -> 0.31695774 | F10: ='[1]stem-seasonal-trade'!E11 -> 1.8815093
A11: 5 | B11: abroad-nores-medium | C11: STEM | D11: summer | E11: ='[1]stem-seasonal-trade'!C12 -> 1.6309195 | F11: ='[1]stem-seasonal-trade'!E12 -> 1.8095095
A12: 5 | B12: abroad-nores-high | C12: STEM | D12: summer | E12: ='[1]stem-seasonal-trade'!C13 -> 3.7980967 | F12: ='[1]stem-seasonal-trade'!E13 -> 1.3064509
A13: 5 | B13: abroad-nores-phaseout | C13: STEM | D13: summer | E13: ='[1]stem-seasonal-trade'!C14 -> 4.7415558 | F13: ='[1]stem-seasonal-trade'!E14 -> 1.3064999
... A25: 8 | B25: abroad-nores-phaseout | C25: STEM | D25: summer | E25: ='[1]stem-seasonal-trade'!C26 -> 4.7415558 | F25: ='[1]stem-seasonal-trade'!E26 -> 1.3064999
A26: 5 | B26: abroad-resnuc-low | C26: Nexus-e | D26: summer | E26: ='[1]nexus-e'!I2 -> 6.7311601 | F26: ='[1]nexus-e'!J2 -> 12.851424
A27: 5 | B27: abroad-resnuc-medium | C27: Nexus-e | D27: summer | E27: ='[1]nexus-e'!I3 -> 1.9976326 | F27: ='[1]nexus-e'!J3 -> 18.182727
A28: 5 | B28: abroad-resnuc-high | C28: Nexus-e | D28: summer | E28: ='[1]nexus-e'!I4 -> 2.0420255 | F28: ='[1]nexus-e'!J4 -> 18.644627
A29: 5 | B29: abroad-resnuc-phaseout | C29: Nexus-e | D29: summer | E29: ='[1]nexus-e'!I5 -> 2.0420255 | F29: ='[1]nexus-e'!J5 -> 18.644627
A30: 5 | B30: abroad-res-low | C30: Nexus-e | D30: summer | E30: ='[1]nexus-e'!I6 -> 2.0420255 | F30: ='[1]nexus-e'!J6 -> 18.644627
A31: 5 | B31: abroad-res-medium | C31: Nexus-e | D31: summer | E31: ='[1]nexus-e'!I7 -> 2.0420255 | F31: ='[1]nexus-e'!J7 -> 18.644627
A32: 5 | B32: abroad-res-high | C32: Nexus-e | D32: summer | E32: ='[1]nexus-e'!I8 -> 2.0420255 | F32: ='[1]nexus-e'!J8 -> 18.644627
A33: 5 | B33: abroad-res-phaseout | C33: Nexus-e | D33: summer | E33: ='[1]nexus-e'!I9 -> 2.0420255 | F33: ='[1]nexus-e'!J9 -> 18.644627
A34: 5 | B34: abroad-nores-low | C34: Nexus-e | D34: summer | E34: ='[1]nexus-e'!I10 -> 12.254425 | F34: ='[1]nexus-e'!J10 -> 4.950673
A35: 5 | B35: abroad-nores-medium | C35: Nexus-e | D35: summer | E35: ='[1]nexus-e'!I11 -> 13.921652 | F35: ='[1]nexus-e'!J11 -> 3.3619055
A36: 5 | B36: abroad-nores-high | C36: Nexus-e | D36: summer | E36: ='[1]nexus-e'!I12 -> 13.921652 | F36: ='[1]nexus-e'!J12 -> 3.3619055
A37: 5 | B37: abroad-nores-phaseout | C37: Nexus-e | D37: summer | E37: ='[1]nexus-e'!I13 -> 13.921652 | F37: ='[1]nexus-e'!J13 -> 3.3619055
... A49: 8 | B49: abroad-nores-phaseout | C49: Nexus-e | D49: summer | E49: ='[1]nexus-e'!I25 -> 13.921652 | F49: ='[1]nexus-e'!J25 -> 3.3619055
A50: 5 | B50: abroad-resnuc-low | C50: SES | D50: summer | E50: {=INDEX('[1]ses-monthly-trade'!N$2:N$25, MATCH(1, (B50='[1]ses-monthly-trade'!M$2:M$25) * ('Seasonal Electricity Trade'!A50='[1]ses-monthly-trade'!L$2:L$25), 0))} -> 4566.1649 | F50: {=INDEX('[1]ses-monthly-trade'!O$2:O$25, MATCH(1, (B50='[1]ses-monthly-trade'!M$2:M$25) * ('Seasonal Electricity Trade'!A50='[1]ses-monthly-trade'!L$2:L$25), 0))} -> 6709.9826
A51: 5 | B51: abroad-resnuc-medium | C51: SES | D51: summer | E51: {=INDEX('[1]ses-monthly-trade'!N$2:N$25, MATCH(1, (B51='[1]ses-monthly-trade'!M$2:M$25) * ('Seasonal Electricity Trade'!A51='[1]ses-monthly-trade'!L$2:L$25), 0))} -> 5541.8977 | F51: {=INDEX('[1]ses-monthly-trade'!O$2:O$25, MATCH(1, (B51='[1]ses-monthly-trade'!M$2:M$25) * ('Seasonal Electricity Trade'!A51='[1]ses-monthly-trade'!L$2:L$25), 0))} -> 9003.3508
A52: 5 | B52: abroad-resnuc-high | C52: SES | D52: summer | E52: {=INDEX('[1]ses-monthly-trade'!N$2:N$25, MATCH(1, (B52='[1]ses-monthly-trade'!M$2:M$25) * ('Seasonal Electricity Trade'!A52='[1]ses-monthly-trade'!L$2:L$25), 0))} -> 5523.2522 | F52: {=INDEX('[1]ses-monthly-trade'!O$2:O$25, MATCH(1, (B52='[1]ses-monthly-trade'!M$2:M$25) * ('Seasonal Electricity Trade'!A52='[1]ses-monthly-trade'!L$2:L$25), 0))} -> 9026.9901
A53: 5 | B53: abroad-resnuc-phaseout | C53: SES | D53: summer | E53: {=INDEX('[1]ses-monthly-trade'!N$2:N$25, MATCH(1, (B53='[1]ses-monthly-trade'!M$2:M$25) * ('Seasonal Electricity Trade'!A53='[1]ses-monthly-trade'!L$2:L$25), 0))} -> 5544.4613 | F53: {=INDEX('[1]ses-monthly-trade'!O$2:O$25, MATCH(1, (B53='[1]ses-monthly-trade'!M$2:M$25) * ('Seasonal Electricity Trade'!A53='[1]ses-monthly-trade'!L$2:L$25), 0))} -> 9005.0188
A54: 5 | B54: abroad-res-low | C54: SES | D54: summer | E54: {=INDEX('[1]ses-monthly-trade'!N$2:N$25, MATCH(1, (B54='[1]ses-monthly-trade'!M$2:M$25) * ('Seasonal Electricity Trade'!A54='[1]ses-monthly-trade'!L$2:L$25), 0))} -> 5809.4751 | F54: {=INDEX('[1]ses-monthly-trade'!O$2:O$25, MATCH(1, (B54='[1]ses-monthly-trade'!M$2:M$25) * ('Seasonal Electricity Trade'!A54='[1]ses-monthly-trade'!L$2:L$25), 0))} -> 9094.1783
A55: 5 | B55: abroad-res-medium | C55: SES | D55: summer | E55: {=INDEX('[1]ses-monthly-trade'!N$2:N$25, MATCH(1, (B55='[1]ses-monthly-trade'!M$2:M$25) * ('Seasonal Electricity Trade'!A55='[1]ses-monthly-trade'!L$2:L$25), 0))} -> 5834.5406 | F55: {=INDEX('[1]ses-monthly-trade'!O$2:O$25, MATCH(1, (B55='[1]ses-monthly-trade'!M$2:M$25) * ('Seasonal Electricity Trade'!A55='[1]ses-monthly-trade'!L$2:L$25), 0))} -> 9070.6907
A56: 5 | B56: abroad-res-high | C56: SES | D56: summer | E56: {=INDEX('[1]ses-monthly-trade'!N$2:N$25, MATCH(1, (B56='[1]ses-monthly-trade'!M$2:M$25) * ('Seasonal Electricity Trade'!A56='[1]ses-monthly-trade'!L$2:L$25), 0))} -> 5775.623 | F56: {=INDEX('[1]ses-monthly-trade'!O$2:O$25, MATCH(1, (B56='[1]ses-monthly-trade'!M$2:M$25) * ('Seasonal Electricity Trade'!A56='[1]ses-monthly-trade'!L$2:L$25), 0))} -> 9128.8635
A57: 5 | B57: abroad-res-phaseout | C57: SES | D57: summer | E57: {=INDEX('[1]ses-monthly-trade'!N$2:N$25, MATCH(1, (B57='[1]ses-monthly-trade'!M$2:M$25) * ('Seasonal Electricity Trade'!A57='[1]ses-monthly-trade'!L$2:L$25), 0))} -> 5819.1122 | F57: {=INDEX('[1]ses-monthly-trade'!O$2:O$25, MATCH(1, (B57='[1]ses-monthly-trade'!M$2:M$25) * ('Seasonal Electricity Trade'!A57='[1]ses-monthly-trade'!L$2:L$25), 0))} -> 9070.4373
A58: 5 | B58: abroad-nores-low | C58: SES | D58: summer | E58: {=INDEX('[1]ses-monthly-trade'!N$2:N$25, MATCH(1, (B58='[1]ses-monthly-trade'!M$2:M$25) * ('Seasonal Electricity Trade'!A58='[1]ses-monthly-trade'!L$2:L$25), 0))} -> 21848.079 | F58: {=INDEX('[1]ses-monthly-trade'!O$2:O$25, MATCH(1, (B58='[1]ses-monthly-trade'!M$2:M$25) * ('Seasonal Electricity Trade'!A58='[1]ses-monthly-trade'!L$2:L$25), 0))} -> 87.846523
A59: 5 | B59: abroad-nores-medium | C59: SES | D59: summer | E59: {=INDEX('[1]ses-monthly-trade'!N$2:N$25, MATCH(1, (B59='[1]ses-monthly-trade'!M$2:M$25) * ('Seasonal Electricity Trade'!A59='[1]ses-monthly-trade'!L$2:L$25), 0))} -> 21848.595 | F59: {=INDEX('[1]ses-monthly-trade'!O$2:O$25, MATCH(1, (B59='[1]ses-monthly-trade'!M$2:M$25) * ('Seasonal Electricity Trade'!A59='[1]ses-monthly-trade'!L$2:L$25), 0))} -> 88.155584
A60: 5 | B60: abroad-nores-high | C60: SES | D60: summer | E60: {=INDEX('[1]ses-monthly-trade'!N$2:N$25, MATCH(1, (B60='[1]ses-monthly-trade'!M$2:M$25) * ('Seasonal Electricity Trade'!A60='[1]ses-monthly-trade'!L$2:L$25), 0))} -> 21849.954 | F60: {=INDEX('[1]ses-monthly-trade'!O$2:O$25, MATCH(1, (B60='[1]ses-monthly-trade'!M$2:M$25) * ('Seasonal Electricity Trade'!A60='[1]ses-monthly-trade'!L$2:L$25), 0))} -> 89.028222
A61: 5 | B61: abroad-nores-phaseout | C61: SES | D61: summer | E61: {=INDEX('[1]ses-monthly-trade'!N$2:N$25, MATCH(1, (B61='[1]ses-monthly-trade'!M$2:M$25) * ('Seasonal Electricity Trade'!A61='[1]ses-monthly-trade'!L$2:L$25), 0))} -> 21841.373 | F61: {=INDEX('[1]ses-monthly-trade'!O$2:O$25, MATCH(1, (B61='[1]ses-monthly-trade'!M$2:M$25) * ('Seasonal Electricity Trade'!A61='[1]ses-monthly-trade'!L$2:L$25), 0))} -> 90.657453
... A73: 8 | B73: abroad-nores-phaseout | C73: SES | D73: summer | E73: {=INDEX('[1]ses-monthly-trade'!N$2:N$25, MATCH(1, (B73='[1]ses-monthly-trade'!M$2:M$25) * ('Seasonal Electricity Trade'!A73='[1]ses-monthly-trade'!L$2:L$25), 0))} -> 21847.681 | F73: {=INDEX('[1]ses-monthly-trade'!O$2:O$25, MATCH(1, (B73='[1]ses-monthly-trade'!M$2:M$25) * ('Seasonal Electricity Trade'!A73='[1]ses-monthly-trade'!L$2:L$25), 0))} -> 85.800051
...
